moex/test-data/head.test.txt
#SYMBOL,SYSTEM,TYPE,MOMENT,ID,ACTION,PRICE,VOLUME,ID_DEAL,PRICE_DEAL
Si73750BC2,C,B,20220131185256610,1892947028292403201,1,1.00000,1,,
Si74250BO2,P,B,20220131185256620,1892947028292403202,1,1.00000,1,,
Si73750BO2,P,B,20220131185256627,1892947028292403203,1,1.00000,1,,
Si74750BO2,P,B,20220131185256627,1892947028292403204,1,1.00000,1,,
Si71000BI2,C,B,20220131185256627,1892947028292403205,1,1.00000,1,,
Si68000BR2,P,B,20220131185256630,1892947028292403207,1,20.00000,50,,
Si90000BC2,C,S,20220131185257133,1892947028292403210,1,1366.00000,1,,
Si78000BC2,C,B,20220131185257137,1892947028292403213,1,355.00000,10,,
Si75000BC2,C,B,20220131185257137,1892947028292403215,1,1.00000,1,,
